<?xml version="1.0" encoding="utf-8"?>
<!-- This URDF was automatically created by SolidWorks to URDF Exporter! Originally created by Stephen Brawner (brawner@gmail.com) 
     Commit Version: 1.6.0-4-g7f85cfe  Build Version: 1.6.7995.38578
     For more information, please see http://wiki.ros.org/sw_urdf_exporter -->
<robot
  name="my_robot">
  <link
    name="base_link">
    <inertial>
      <origin
        xyz="-1.31453754602346E-05 0.0145989685767295 0.0128735596572317"
        rpy="0 0 0" />
      <mass
        value="0.0291817522897115" />
      <inertia
        ixx="2.26096677078734E-05"
        ixy="1.05080685382153E-09"
        ixz="1.49707222944589E-09"
        iyy="7.10731627926214E-06"
        iyz="-7.355107142587E-07"
        izz="2.69894564594657E-05" />
    </inertial>
    <visual>
      <origin
        xyz="0 0 0"
        rpy="0 0 0" />
      <geometry>
        <mesh
          filename="package://my_robot/meshes/base_link.STL" />
      </geometry>
      <material
        name="">
        <color
          rgba="0.792156862745098 0.819607843137255 0.933333333333333 1" />
      </material>
    </visual>
    <collision>
      <origin
        xyz="0 0 0"
        rpy="0 0 0" />
      <geometry>
        <mesh
          filename="package://my_robot/meshes/base_link.STL" />
      </geometry>
    </collision>
  </link>
  <link
    name="link_1">
    <inertial>
      <origin
        xyz="0.00223414762984723 0.00830104302441679 0.00906431037667552"
        rpy="0 0 0" />
      <mass
        value="0.00420634678285121" />
      <inertia
        ixx="5.55087733615501E-07"
        ixy="6.36179223881654E-13"
        ixz="-5.71540420351045E-13"
        iyy="3.34497011562759E-07"
        iyz="-2.3665444278581E-07"
        izz="2.92803242780953E-07" />
    </inertial>
    <visual>
      <origin
        xyz="0 0 0"
        rpy="0 0 0" />
      <geometry>
        <mesh
          filename="package://my_robot/meshes/link_1.STL" />
      </geometry>
      <material
        name="">
        <color
          rgba="0.866666666666667 0.486274509803922 0.0549019607843137 1" />
      </material>
    </visual>
    <collision>
      <origin
        xyz="0 0 0"
        rpy="0 0 0" />
      <geometry>
        <mesh
          filename="package://my_robot/meshes/link_1.STL" />
      </geometry>
    </collision>
  </link>
  <joint
    name="arm_1"
    type="revolute">
    <origin
      xyz="0.0075 0.03703 0.044564"
      rpy="0 0 0" />
    <parent
      link="base_link" />
    <child
      link="link_1" />
    <axis
      xyz="1 0 0" />
    <limit
      lower="-1.5708"
      upper="3.1416"
      effort="10"
      velocity="10" />
  </joint>
  <link
    name="link_2">
    <inertial>
      <origin
        xyz="-0.0043157 0.010971 -0.0096757"
        rpy="0 0 0" />
      <mass
        value="0.005347" />
      <inertia
        ixx="2.5247E-07"
        ixy="2.3881E-11"
        ixz="-3.6218E-11"
        iyy="2.063E-07"
        iyz="6.5887E-08"
        izz="1.6953E-07" />
    </inertial>
    <visual>
      <origin
        xyz="0 0 0"
        rpy="0 0 0" />
      <geometry>
        <mesh
          filename="package://my_robot/meshes/link_2.STL" />
      </geometry>
      <material
        name="">
        <color
          rgba="0.86667 0.48627 0.054902 1" />
      </material>
    </visual>
    <collision>
      <origin
        xyz="0 0 0"
        rpy="0 0 0" />
      <geometry>
        <mesh
          filename="package://my_robot/meshes/link_2.STL" />
      </geometry>
    </collision>
  </link>
  <joint
    name="arm_2"
    type="revolute">
    <origin
      xyz="-0.0032658 0.021983 0.024004"
      rpy="0 0 0" />
    <parent
      link="link_1" />
    <child
      link="link_2" />
    <axis
      xyz="1 0 0" />
    <limit
      lower="-1.5708"
      upper="1.5708"
      effort="10"
      velocity="10" />
  </joint>
  <link
    name="link_3">
    <inertial>
      <origin
        xyz="-0.0040462500171085 8.98969064536126E-08 -4.51286701875185E-08"
        rpy="0 0 0" />
      <mass
        value="0.00249693932535124" />
      <inertia
        ixx="1.69120898530834E-07"
        ixy="-2.97875097863566E-14"
        ixz="5.06710793463879E-16"
        iyy="9.96401080341647E-08"
        iyz="2.03546979033232E-14"
        izz="9.96401933922976E-08" />
    </inertial>
    <visual>
      <origin
        xyz="0 0 0"
        rpy="0 0 0" />
      <geometry>
        <mesh
          filename="package://my_robot/meshes/link_3.STL" />
      </geometry>
      <material
        name="">
        <color
          rgba="0.992156862745098 0.835294117647059 0 1" />
      </material>
    </visual>
    <collision>
      <origin
        xyz="0 0 0"
        rpy="0 0 0" />
      <geometry>
        <mesh
          filename="package://my_robot/meshes/link_3.STL" />
      </geometry>
    </collision>
  </link>
  <joint
    name="banh_sau_1"
    type="continuous">
    <origin
      xyz="0.039139 -0.03075 0.0075001"
      rpy="0 0 0" />
    <parent
      link="base_link" />
    <child
      link="link_3" />
    <axis
      xyz="-1 0 0" />
    <limit
      effort="20"
      velocity="20" />
  </joint>
  <link
    name="link_5">
    <inertial>
      <origin
        xyz="8.20020440439606E-12 1.18081321283381E-07 2.67257998735199E-08"
        rpy="0 0 0" />
      <mass
        value="0.00249697642159156" />
      <inertia
        ixx="1.69125000069436E-07"
        ixy="-3.09754433163804E-14"
        ixz="-7.03839122429789E-14"
        iyy="9.96427996052339E-08"
        iyz="-1.37493723279831E-13"
        izz="9.96424903226141E-08" />
    </inertial>
    <visual>
      <origin
        xyz="0 0 0"
        rpy="0 0 0" />
      <geometry>
        <mesh
          filename="package://my_robot/meshes/link_5.STL" />
      </geometry>
      <material
        name="">
        <color
          rgba="0.992156862745098 0.835294117647059 0 1" />
      </material>
    </visual>
    <collision>
      <origin
        xyz="0 0 0"
        rpy="0 0 0" />
      <geometry>
        <mesh
          filename="package://my_robot/meshes/link_5.STL" />
      </geometry>
    </collision>
  </link>
  <joint
    name="banh_sau_2"
    type="continuous">
    <origin
      xyz="-0.035093 -0.03075 0.0075"
      rpy="0 0 0" />
    <parent
      link="base_link" />
    <child
      link="link_5" />
    <axis
      xyz="-1 0 0" />
    <limit
      effort="20"
      velocity="20" />
  </joint>
  <link
    name="link_4">
    <inertial>
      <origin
        xyz="-6.96298574354159E-12 1.08703289206785E-07 -2.48209927320754E-08"
        rpy="0 0 0" />
      <mass
        value="0.00249697638863783" />
      <inertia
        ixx="1.69124999181447E-07"
        ixy="3.00944884872809E-14"
        ixz="-2.41404350978596E-14"
        iyy="9.96427804379049E-08"
        iyz="6.18187286896431E-14"
        izz="9.96425075153552E-08" />
    </inertial>
    <visual>
      <origin
        xyz="0 0 0"
        rpy="0 0 0" />
      <geometry>
        <mesh
          filename="package://my_robot/meshes/link_4.STL" />
      </geometry>
      <material
        name="">
        <color
          rgba="0.992156862745098 0.835294117647059 0 1" />
      </material>
    </visual>
    <collision>
      <origin
        xyz="0 0 0"
        rpy="0 0 0" />
      <geometry>
        <mesh
          filename="package://my_robot/meshes/link_4.STL" />
      </geometry>
    </collision>
  </link>
  <joint
    name="banh_truoc_1"
    type="continuous">
    <origin
      xyz="0.035093 0.03075 0.0075"
      rpy="0 0 0" />
    <parent
      link="base_link" />
    <child
      link="link_4" />
    <axis
      xyz="1 0 0" />
    <limit
      effort="20"
      velocity="20" />
  </joint>
  <link
    name="link_6">
    <inertial>
      <origin
        xyz="-7.06587566234873E-14 1.12056228369212E-07 2.7380035182243E-08"
        rpy="0 0 0" />
      <mass
        value="0.00249693933126322" />
      <inertia
        ixx="1.69120899399444E-07"
        ixy="4.11806883793746E-14"
        ixz="4.10356660453772E-14"
        iyy="9.96401511816989E-08"
        iyz="6.47487705818278E-14"
        izz="9.96401513108857E-08" />
    </inertial>
    <visual>
      <origin
        xyz="0 0 0"
        rpy="0 0 0" />
      <geometry>
        <mesh
          filename="package://my_robot/meshes/link_6.STL" />
      </geometry>
      <material
        name="">
        <color
          rgba="0.992156862745098 0.835294117647059 0 1" />
      </material>
    </visual>
    <collision>
      <origin
        xyz="0 0 0"
        rpy="0 0 0" />
      <geometry>
        <mesh
          filename="package://my_robot/meshes/link_6.STL" />
      </geometry>
    </collision>
  </link>
  <joint
    name="banh_truoc_2"
    type="continuous">
    <origin
      xyz="-0.035093 0.03075 0.0074999"
      rpy="0 0 0" />
    <parent
      link="base_link" />
    <child
      link="link_6" />
    <axis
      xyz="1 0 0" />
    <limit
      effort="20"
      velocity="20" />
  </joint>
  <link
    name="link_7">
    <inertial>
      <origin
        xyz="0 0 0"
        rpy="0 0 0" />
      <mass
        value="0" />
      <inertia
        ixx="0"
        ixy="0"
        ixz="0"
        iyy="0"
        iyz="0"
        izz="0" />
    </inertial>
    <visual>
      <origin
        xyz="0 0 0"
        rpy="0 0 0" />
      <geometry>
        <mesh
          filename="package://my_robot/meshes/link_7.STL" />
      </geometry>
      <material
        name="">
        <color
          rgba="1 1 1 1" />
      </material>
    </visual>
    <collision>
      <origin
        xyz="0 0 0"
        rpy="0 0 0" />
      <geometry>
        <mesh
          filename="package://my_robot/meshes/link_7.STL" />
      </geometry>
    </collision>
  </link>
  <joint
    name="lidar"
    type="fixed">
    <origin
      xyz="-0.000187931464256533 0.0525 0.00771984791654629"
      rpy="0 0 0" />
    <parent
      link="base_link" />
    <child
      link="link_7" />
    <axis
      xyz="0 0 0" />
    </joint>
  <gazebo>
    <plugin name="differential_drive_controller" filename="libgazebo_ros_diff_drive.so">
      <updateRate>20</updateRate>
      <leftJoint>banh_sau_2</leftJoint>
      <rightJoint>banh_sau_1</rightJoint>
      <wheelSeparation>0.4</wheelSeparation>
      <wheelDiameter>0.2</wheelDiameter>
      <wheelTorque>20</wheelTorque>
      <commandTopic>cmd_vel</commandTopic>
      <odometryTopic>odom</odometryTopic>
      <robotBaseFrame>base_link</robotBaseFrame>
    </plugin>
  </gazebo>

  <transmission name="tran1">
    <type>transmission_interface/SimpleTransmission</type>
    <joint name="arm_1">
      <hardwareInterface>hardware_interface/PositionJointInterface</hardwareInterface>
    </joint>
    <actuator name="motor1">
      <mechanicalReduction>1</mechanicalReduction>
    </actuator>
  </transmission>

  <transmission name="tran2">
    <type>transmission_interface/SimpleTransmission</type>
    <joint name="arm_2">
      <hardwareInterface>hardware_interface/PositionJointInterface</hardwareInterface>
    </joint>
    <actuator name="motor2">
      <mechanicalReduction>1</mechanicalReduction>
    </actuator>
  </transmission>

  <gazebo>
    <plugin name="gazebo_ros_control" filename="libgazebo_ros_control.so">
      <robotNamespace>/</robotNamespace>
    </plugin>
  </gazebo>
  <gazebo reference="link_7">
    <sensor type="ray" name="head_hokuyo_sensor">
      <pose>0 0 0 0 0 0</pose>
      <visualize>true</visualize>
      <update_rate>40</update_rate>
      <ray>
        <scan>
          <horizontal>
            <samples>720</samples>
            <resolution>1</resolution>
            <min_angle>-3.14159</min_angle> <max_angle>3.14159</max_angle>  </horizontal>
        </scan>
        <range>
          <min>0.10</min>
          <max>30.0</max>
          <resolution>0.01</resolution>
        </range>
        <noise>
          <type>gaussian</type>
          <mean>0.0</mean>
          <stddev>0.01</stddev>
        </noise>
      </ray>
      <plugin name="gazebo_ros_head_hokuyo_controller" filename="libgazebo_ros_laser.so">
        <topicName>/scan</topicName>
        <frameName>link_7</frameName> </plugin>
    </sensor>
  </gazebo>
  <link name="imu_link">
    <visual>
      <geometry>
        <box size="0.02 0.02 0.005"/> 
      </geometry>
      <material name="white">
        <color rgba="1 1 1 1"/>
      </material>
    </visual>
    <inertial>
      <mass value="0.01" />
      <inertia ixx="1e-6" ixy="0" ixz="0" iyy="1e-6" iyz="0" izz="1e-6" />
    </inertial>
  </link>

  <joint name="imu_joint" type="fixed">
    <parent link="base_link"/>
    <child link="imu_link"/>
    <origin xyz="0 0 0.01" rpy="0 0 0"/> 
  </joint>
  <gazebo reference="imu_link">
    <gravity>true</gravity>
    <sensor name="imu_sensor" type="imu">
      <always_on>true</always_on>
      <update_rate>100</update_rate>
      <visualize>true</visualize>
      <topic>__default_topic__</topic>
      <plugin filename="libgazebo_ros_imu_sensor.so" name="imu_plugin">
        <topicName>imu</topicName>         <bodyName>imu_link</bodyName>
        <updateRateHZ>100.0</updateRateHZ>
        <gaussianNoise>0.0</gaussianNoise> <xyzOffset>0 0 0</xyzOffset>     
        <rpyOffset>0 0 0</rpyOffset>
        <frameName>imu_link</frameName>    </plugin>
      <pose>0 0 0 0 0 0</pose>
    </sensor>
  </gazebo>
 <joint name="camera_joint" type="fixed">
    <parent link="base_link"/>
    <child link="camera_link"/>
    <origin xyz="0 0 0.08" rpy="0 0 1.57"/> 
  </joint>

  <link name="camera_link">
    <visual>
      <geometry>
        <box size="0.02 0.05 0.03"/> 
      </geometry>
      <material name="red">
        <color rgba="1 0 0 1"/>
      </material>
    </visual>
    <inertial>
      <mass value="0.01" />
      <inertia ixx="1e-6" ixy="0" ixz="0" iyy="1e-6" iyz="0" izz="1e-6" />
    </inertial>
  </link>
  <gazebo reference="camera_link">
  <sensor type="camera" name="main_camera">
    <update_rate>30.0</update_rate>
    <visualize>true</visualize> 
    <camera name="head">
      <horizontal_fov>1.3962634</horizontal_fov> 
      <image>
        <width>640</width>
        <height>480</height>
        <format>R8G8B8</format>
      </image>
      <clip>
        <near>0.02</near>
        <far>300</far>
      </clip>
    </camera>
    <plugin name="camera_controller" filename="libgazebo_ros_camera.so">
      <alwaysOn>true</alwaysOn>
      <cameraName>robot/camera</cameraName>
      <imageTopicName>image_raw</imageTopicName>
      <cameraInfoTopicName>camera_info</cameraInfoTopicName>
      <frameName>camera_link</frameName>
    </plugin>
  </sensor>
  </gazebo>
</robot>